Workbook

Sheet 选型原则
A1: bot-metric 指标选型：结果与依据
A2: 结论：bot-metric 一共输出 65 项指标。其中 12 项工具没有给出计算方式，不参与评估；其余 53 项里选入 15 项，不选入 38 项。选入的 15 项各回答一个明确的问题（第一节）；不选入的 38 项分成 6 组，每组只有一个主因（第三节）。想查某一项具体为什么，到「指标清单」页按名称筛选。
A3: 阅读顺序：第一节看选了什么，第二节看怎么选，第三节看没选的为什么，第四节核对数量。术语见最后一页「术语说明」。
A5: 一、选入的 15 项：每项回答什么问题
A6: 度量级别 | B6: 指标 | C6: 它回答的问题 | D6: 拟展示位置 | E6: 呈现方式 | F6: 主题
A7: 函数级 | B7: 平均函数代码行 | C7: 函数平均有多长（有效代码行） | D7: 文件状态栏、工作区面板 | E7: 目标呈现（带阈值与达标态） | F7: 代码规模
A8: 函数级 | B8: 超大函数比例 | C8: 有多少函数超大（超过 50 行） | D8: 文件状态栏、工作区面板 | E8: 诊断（带位置） | F8: 代码规模
A9: 函数级 | B9: 平均圈复杂度 | C9: 函数平均有多复杂（圈复杂度） | D9: 文件状态栏、工作区面板 | E9: 目标呈现（带阈值与达标态） | F9: 复杂度
A10: 函数级 | B10: 超大圈复杂度比例 | C10: 有多少函数圈复杂度超过 20 | D10: 文件状态栏、工作区面板 | E10: 诊断（带位置） | F10: 复杂度
A11: 函数级 | B11: 平均 CCA 复杂度 | C11: 按 CCA 算，函数平均有多复杂 | D11: 文件状态栏、工作区面板（与圈复杂度并列） | E11: 参考值（不设阈值、不标红） | F11: 复杂度
A12: 函数级 | B12: CCA 超限比例 | C12: 有多少函数 CCA 复杂度超过 20 | D12: 文件状态栏、工作区面板（与圈复杂度超限比例并列） | E12: 参考值（不设阈值、不标红） | F12: 复杂度
A13: 函数级 | B13: 函数级总体规则遵从度 | C13: 有多少函数没有触发任何规则 | D13: 文件状态栏（底栏与悬停画像） | E13: 诊断（带位置） | F13: 规则达标率
A14: 模块级 | B14: 平均文件代码行 | C14: 文件平均有多长（有效代码行） | D14: 工作区面板、门禁栏 | E14: 目标呈现（带阈值与达标态） | F14: 代码规模
A15: 模块级 | B15: 超大文件比例 | C15: 有多少文件超大（超过 2000 行） | D15: 工作区面板 | E15: 诊断（带位置） | F15: 代码规模
A16: 模块级 | B16: 超大目录比例 | C16: 有多少目录的直接子项过多（超过 50） | D16: 工作区面板 | E16: 参考值（不设阈值、不标红） | F16: 代码规模
A17: 项目级 | B17: 代码规模（有效代码行） | C17: 工程（或单个文件）有多少行有效代码 | D17: 文件状态栏（悬停提示）、工作区面板、门禁栏 | E17: 目标呈现（带阈值与达标态） | F17: 代码规模
... A21: 项目级 | B21: 注释代码密度 | C21: 每千行有效代码里有多少段被注释掉的代码 | D21: 文件状态栏、工作区面板 | E21: 参考值（不设阈值、不标红） | F21: 代码整洁
A22: 参考值 = 没有对应规则或质量目标，只显示数值，不设阈值、不标红。选入项里：7 项对应规则、7 项对应质量目标（其中 3 项两者兼有）、4 项只作参考值，计数见「规则与门禁」页。
A24: 二、怎么选
A25: 插件有两个职责：一是提示可修复的问题（改），二是评估手上代码的质量水平（评）。只有指标自身的性质决定选不选（三条准入条件）；规则和质量目标只决定选中之后怎么展示，不决定选不选。没有一项是因为「工具没有为它写规则」而被排除的。
A26: 准入条件 | B26: 名称 | C26: 什么意思 | D26: 本表里的例子
A27: A1 | B27: 有区分度 | C27: 不与已选项定义恒等、严格互补或一一对应。不带新信息的数，再有道理也不该占展示位。 | D27: 覆盖率类 18 项：同一粒度内 6 项取值恒等（都是 110/110），实际只有 1 个信息。CCA 满足度与 CCA 超限比例之和恒为 1。
A28: A2 | B28: 方向可接受 | C28: 改善这个数的做法必须是开发者认同的更好；如果只能靠更糟的写法把它降下来，展示它反而有害。 | D28: 圈复杂度对 6 分支的宽分派 match 打 6 分，CCA 只打 2 分。只盯圈复杂度，可能把清晰的 match 拆成嵌套 if。所以圈复杂度保留（它被质量目标和规则使用），并列展示 CCA 校正。
A29: A3 | B29: 尺度有效 | C29: 在它的展示范围内，分母不能退化成 1 或 0，也不能因分子太小而失真。 | D29: 项目级遵从度分母恒为 1，只有 0 / 1 两个值。静态告警密度：工作区 1.25 条/千行，按光标处取值升到 16.2。
A31: 展示规则 | B31: 名称 | C31: 内容
A32: 落点 B | B32: 放在哪里 | C32: 判定对象在编辑器里有对应物的，落在对应物上（函数、文件）；没有对应物的落在面板。项目级指标进面板，不等于不选入。
A33: 呈现 C | B33: 怎么显示 | C33: 有对应规则：作诊断，带代码位置。有对应质量目标：作目标呈现，带阈值和达标状态。两者都没有：只作参考值，不设阈值、不标红。
A34: 预算 D | B34: 放不下时 | C34: 同一个展示位能放的数有上限，超出时按「有位置 > 有门禁后果 > 参考值」排序取舍。这是排序问题，不是准入问题。
A36: 三、不选入的 38 项：6 组主因
A37: 每一项只归入一组（它最主要的原因）；有的还同时触发第二条准入条件，写在「触发的准入条件」里。「产品取舍」一组不是准入条件的结论，是展示上的决定。项数由「指标清单」页的「不选入的主因」列自动统计。
A38: 分组 | B38: 一句话主因 | C38: 说明 | D38: 包含哪些指标 | E38: 项数 | F38: 触发的准入条件
A39: 覆盖率类 | B39: 几乎恒为 100%，解析失败另有专门提示 | C39: 覆盖率 = 成功解析的比例。公式里没有「质量维度」参数，所以同一粒度内的 6 项（总体 + 5 个维度）取值恒等，实际只携带 1 个信息；这 1 个信息又只有在文件解析失败时才会变，而解析失败已经由分析状态「降级」和 BM201 语法错误诊断表达。 | D39: 文件级 6 项、函数级 6 项、项目级 6 项 | E39: =COUNTIF(指标清单!$M$2:$M$54,$A39) -> 18 | F39: A1 有区分度
A40: 维度遵从度 | B40: 只是把规则命中按质量维度重新分组，且组内数值相同 | C40: 质量维度（可维护、可读、可靠、安全、可测试）是规则的分组：知道命中了哪条规则，就知道哪些维度不达标。五个维度里，可维护、可读、可测试涉及的规则完全相同，安全、可靠涉及的规则完全相同，所以五项实际只有两个不同的值。门禁栏的「问题按规则分布」比它更细。 | D40: 文件级 5 项、函数级 5 项 | E40: =COUNTIF(指标清单!$M$2:$M$54,$A40) -> 10 | F40: A1 有区分度
A41: 项目级遵从度 | B41: 只有 0 和 1 两个取值，等价于门禁的通过 / 阻塞 | C41: 项目级把整个分析范围当作 1 个单位，默认的 physical 聚合下只能是通过（1）或不通过（0）。这个结论就是门禁栏已展示的门禁结论（gate.status）。 | D41: 总体 1 项、5 个维度共 5 项 | E41: =COUNTIF(指标清单!$M$2:$M$54,$A41) -> 6 | F41: A1 有区分度；A3 尺度有效
A42: CCA 满足度 | B42: 与「CCA 超限比例」互补，两数相加恒为 1 | C42: 满足度 = CCA 复杂度 ≤ 20 的函数占比，超限比例 = CCA 复杂度 > 20 的占比，知道一个就知道另一个。 | D42: CCA 阈值满足度 1 项 | E42: =COUNTIF(指标清单!$M$2:$M$54,$A42) -> 1 | F42: A1 有区分度
A43: 告警类 | B43: 与编辑器里已有的告警重复，或范围越小越失真 | C43: 编译告警密度统计的告警在 rust-analyzer 里已经直接显示，且依赖本机工具链；静态告警密度的分子就是已逐条列出的诊断，比率随范围缩小而失真。 | D43: 编译告警密度、静态告警密度 | E43: =COUNTIF(指标清单!$M$2:$M$54,$A43) -> 2 | F43: A1 有区分度；静态告警密度另触发 A3
A44: 产品取舍 | B44: 产品决定不摆达标率：面板给的是结论与按规则的分布，不是一个要读者自己判断好坏的比例 | C44: 文件达标率（rules.conformity.total）本身有区分度，也过了 A2、A3，不是被准入条件排除的，是使用界面时的取舍：一个比例让读者自己判断「77.3% 算好还是不好」，而门禁栏已经给出结论（已阻塞、52 条）与按规则的分布，面板上再摆一个比例是重复的信息。所以工作区面板不摆达标率；函数达标率 rules.conformity.function 保留，但只出现在文件状态栏（底栏「函数达标 47/48」与悬停画像）。这一项在目录里 selected 设为 false，理由写作「界面不摆达标率」；要恢复，把 selected 改回 true 并给它一个 panel 部件即可，不动代码。 | D44: 文件达标率 1 项 | E44: =COUNTIF(指标清单!$M$2:$M$54,$A44) -> 1 | F44: 无（不是准入条件的结论，是展示取舍）
A45: 合计 | E45: =SUM(E39:E44) -> 38
A47: 四、数量核对
A48: 步骤 | B48: 说明 | C48: 数量
...

Sheet 指标清单
A1: 序号 | B1: 度量级别 | C1: 主题 | D1: 指标名称（中文） | E1: 结论 | F1: 一句话理由 | G1: 详细说明（为什么选入 / 为什么不选入） | H1: 拟展示位置 | I1: 呈现方式 | J1: 对应规则 | K1: 对应质量目标 | L1: 展示限制（哪些位置不展示、为什么） | M1: 不选入的主因（分组） | N1: 触发的准入条件 | O1: 判定对象 | P1: 指标标识（bot-metric id） | Q1: 默认阈值 / 参数 | R1: 分子（怎么数） | S1: 分母（除以谁） | T1: 能否按光标处取值 | U1: 工作区实测（ripgrep 全量） | V1: 本文件实测（hiargs.rs） | W1: 光标处实测（from_low_args） | X1: 工具分类
A2: 1 | B2: 函数级 | C2: 代码规模 | D2: 平均函数代码行 | E2: 选入 | F2: 函数平均有多长（有效代码行） | G2: 被质量目标 max_average_function_lines（≤ 30 行）考核，实测 8.52 行，达标。 | H2: 文件状态栏、工作区面板 | I2: 目标呈现（带阈值与达标态） | J2: — | K2: max_average_function_lines（≤ 30 行） | L2: 函数悬停里，没有问题的函数取这一项在该函数（语法项投影）上的值当作「函数体行数」；命中 BM001 的函数改用规则条目里的实际值，更准。投影区域含闭包或嵌套 fn 时得到的是区域平均，会比函数自己的行数小（from_low_args 实测区域平均 41.2，规则条目给出 185），见设计文档 R-2。文件状态栏与工作区面板展示的是本文件、工作区范围的平均。 | M2: — | N2: — | O2: callable | P2: function.lines.average | Q2: 无阈值（质量目标 ≤ 30 行） | R2: 所有 callable 函数体 NBNC 行数之和（函数体按 `{` 所在行到 `}` 所在行计，`{` 与签名同行时该行计入） | S2: callable 数量（自由函数、含嵌套 fn、impl 方法与关联函数、带默认体的 trait 方法；不含闭包） | T2: 能 | U2: 8.52 行（20,574 / 2,414） | V2: 19.71 行（946 / 48） | W2: 41.2 行（206 / 5） | X2: 基础度量
A3: 2 | B3: 函数级 | C3: 代码规模 | D3: 超大函数比例 | E3: 选入 | F3: 有多少函数超大（超过 50 行） | G3: 对应规则 BM001「函数过长」，读作「共 N 个函数，其中 M 个超大」（本文件 1/48，工作区 38/2,414）。 | H3: 文件状态栏、工作区面板 | I3: 诊断（带位置） | J3: BM001 | K3: — | L3: 按光标处取值时只会是 0 或 1，悬停不展示这一项本身（悬停里的函数体行数取它在目录里 valueMetric 指向的平均指标）；具体哪个函数过长由 BM001 诊断提示。 | M3: — | N3: — | O3: callable | P3: function.lines.huge_ratio | Q3: 函数体超过 50 行算超大 | R3: 函数体 NBNC 严格大于阈值的 callable 数 | S3: callable 数量 | T3: 能 | U3: 1.57%（38 / 2,414） | V3: 2.08%（1 / 48） | W3: 20.0%（1 / 5） | X3: 基础度量
A4: 3 | B4: 函数级 | C4: 复杂度 | D4: 平均圈复杂度 | E4: 选入 | F4: 函数平均有多复杂（圈复杂度） | G4: 被质量目标 max_average_cyclomatic（≤ 5）考核，实测 2.10，达标。圈复杂度会给写法清晰的宽分派 match 打高分，所以并列展示 CCA 两项作对照，而不是把它删掉。 | H4: 文件状态栏、工作区面板 | I4: 目标呈现（带阈值与达标态） | J4: — | K4: max_average_cyclomatic（≤ 5） | L4: 函数悬停里，没有问题的函数取这一项在该函数（语法项投影）上的值当作「圈复杂度」；命中 BM004 的函数改用规则条目里的实际值。区域含闭包时是区域平均（from_low_args 实测 9.2，规则条目给出 34），见设计文档 R-2。 | M4: — | N4: — | O4: callable | P4: complexity.cyclomatic.average | Q4: 无阈值（质量目标 ≤ 5） | R4: 所有 callable 的圈复杂度之和（初值 1，遇 if / for / loop / while / match 分支（首分支不计）/ `?` / let-else / && / || 各加 1） | S4: callable 数量 | T4: 能 | U4: 2.10（5,068 / 2,414） | V4: 4.52（217 / 48） | W4: 9.20（46 / 5） | X4: 基础度量
A5: 4 | B5: 函数级 | C5: 复杂度 | D5: 超大圈复杂度比例 | E5: 选入 | F5: 有多少函数圈复杂度超过 20 | G5: 对应规则 BM004「函数复杂度过高」。诊断文本里直接写出具体数字（如圈复杂度 34，上限 20），是单个函数复杂度唯一准确的来源；与「超大函数比例」配对，出现在文件状态栏悬停的画像里。 | H5: 文件状态栏、工作区面板 | I5: 诊断（带位置） | J5: BM004 | K5: — | L5: 按光标处取值时只会是 0 或 1，悬停不展示这一项本身（悬停里的圈复杂度取它在目录里 valueMetric 指向的平均指标）。 | M5: — | N5: — | O5: callable | P5: complexity.cyclomatic.huge_ratio | Q5: 圈复杂度超过 20 算超大 | R5: 圈复杂度严格大于阈值的 callable 数 | S5: callable 数量 | T5: 能 | U5: 0.25%（6 / 2,414） | V5: 2.08%（1 / 48） | W5: 20.0%（1 / 5） | X5: 基础度量
A6: 5 | B6: 函数级 | C6: 复杂度 | D6: 平均 CCA 复杂度 | E6: 选入 | F6: 按 CCA 算，函数平均有多复杂 | G6: CCA 是圈复杂度的变体：match 的各分支体都很简单时，整条 match 只算 1，而不是按分支数累加。圈复杂度会给写法清晰的宽分派 match 很高的分（实测 6 分支 match：圈复杂度 6，CCA 2），开发者为了降分可能把清晰的 match 拆成嵌套 if，代码反而更差。两者并列，能让人看出「分高是因为分派，不是真复杂」。 过 A1：对 match 的算法不同，数值不同，不是重复。过 A2：降低 CCA 不会鼓励更糟的写法。没有对应规则或质量目标，只作参考值，不设阈值、不标红。 | H6: 文件状态栏、工作区面板（与圈复杂度并列） | I6: 参考值（不设阈值、不标红） | J6: — | K6: — | L6: — | M6: — | N6: — | O6: callable | P6: complexity.cca.average | Q6: 无阈值 | R6: 所有 callable 的 CCA 复杂度之和（match 的各分支体都不含决策点时整条 match 只加 1，否则与圈复杂度同） | S6: callable 数量 | T6: 能 | U6: 2.02（4,877 / 2,414） | V6: 4.29（206 / 48） | W6: 9.00（45 / 5） | X6: 基础度量
A7: 6 | B7: 函数级 | C7: 复杂度 | D7: CCA 超限比例 | E7: 选入 | F7: 有多少函数 CCA 复杂度超过 20 | G7: 与圈复杂度的超限比例并列，两者的差就是被圈复杂度高估的 match 分派函数（ripgrep 实测 6 个对 5 个，差的那个是 main.rs 里的 run），可用来判断 BM004 的某条命中是不是误报。没有对应规则或质量目标，只作参考值。 | H7: 文件状态栏、工作区面板（与圈复杂度超限比例并列） | I7: 参考值（不设阈值、不标红） | J7: — | K7: — | L7: — | M7: — | N7: — | O7: callable | P7: complexity.cca.huge_ratio | Q7: CCA 复杂度超过 20 算超限 | R7: CCA 复杂度严格大于阈值的 callable 数 | S7: callable 数量 | T7: 能 | U7: 0.21%（5 / 2,414） | V7: 2.08%（1 / 48） | W7: 20.0%（1 / 5） | X7: 基础度量
A8: 7 | B8: 函数级 | C8: 规则达标率 | D8: 函数级总体规则遵从度 | E8: 选入 | F8: 有多少函数没有触发任何规则 | G8: 汇总 BM001、BM002、BM004 三条函数级规则，实测 2,372/2,414（98.3%）。函数粒度上只保留「总体」这一项：按质量维度切分的五项互相重复，见「不选入」。它是文件状态栏底栏「函数达标 47/48」的来源，也是悬停画像的第一行；工作区面板不摆它。 | H8: 文件状态栏（底栏与悬停画像） | I8: 诊断（带位置） | J8: BM001、BM002、BM004 | K8: — | L8: 解析失败的文件会被算进分母。默认的 unknown_policy = fail 下，编辑中的一处语法错误就会让达标率骤降，所以需要配成 unknown_policy = exclude（见设计文档 DD-5）。 | M8: — | N8: — | O8: callable | P8: rules.conformity.function | Q8: 命中任一相关规则即不达标；解析失败的文件按不达标计 | R8: 没有命中任何函数级相关规则的 callable 数 | S8: callable 数量（unknown_policy = fail 时再加解析失败的文件数） | T8: 不能 | U8: 98.3%（2,372 / 2,414） | V8: 97.9%（47 / 48） | W8: — | X8: 规则统计指标
A9: 8 | B9: 函数级 | C9: 复杂度 | D9: CCA 阈值满足度 | E9: 不选入 | F9: 与「CCA 超限比例」互补，两数相加恒为 1 | G9: 满足度是 CCA 复杂度 ≤ 20 的函数占比，超限比例是 > 20 的占比，两者之和恒为 1（实测 2,409/2,414 与 5/2,414），知道一个就知道另一个，不带新信息。另外它是全工具唯一用「小于等于」判定的指标，方向与相邻指标相反，并排展示容易读反。CCA 保留平均值和超限比例两项。 | H9: 不展示 | I9: — | J9: — | K9: — | L9: — | M9: CCA 满足度 | N9: A1 有区分度 | O9: callable | P9: complexity.cca.adequacy | Q9: CCA 复杂度 ≤ 20 算满足 | R9: CCA 复杂度小于等于阈值的 callable 数 | S9: callable 数量 | T9: 能 | U9: 99.8%（2,409 / 2,414） | V9: 97.9%（47 / 48） | W9: 80.0%（4 / 5） | X9: 基础度量
A10: 9 | B10: 函数级 | C10: 规则达标率 | D10: 函数级可维护规则遵从度 | E10: 不选入 | F10: 只是把规则命中按质量维度重新分组，且组内数值相同 | G10: 质量维度是规则的分组：知道命中了哪条规则，就知道哪些维度不达标。函数级的可维护、可读、可测试三项涉及的规则完全相同（BM001、BM004），本项与可读、可测试同值（工作区实测 2,375 / 2,414），五个维度实际只有两个不同的值。门禁栏的「问题按规则分布」比它更细，这里不再重复。 | H10: 不展示 | I10: — | J10: 涉及部分规则（按维度筛选） | K10: — | L10: — | M10: 维度遵从度 | N10: A1 有区分度 | O10: callable | P10: rules.conformity.function.maintainability | Q10: 解析失败的文件按不达标计（unknown_policy = fail） | R10: 没有命中任何函数级相关规则的 callable 数 | S10: callable 数量（unknown_policy = fail 时再加解析失败的文件数） | T10: 不能 | U10: 98.4%（2,375 / 2,414） | V10: 97.9%（47 / 48） | W10: — | X10: 规则统计指标
A11: 10 | B11: 函数级 | C11: 规则达标率 | D11: 函数级可读规则遵从度 | E11: 不选入 | F11: 只是把规则命中按质量维度重新分组，且组内数值相同 | G11: 质量维度是规则的分组：知道命中了哪条规则，就知道哪些维度不达标。函数级的可维护、可读、可测试三项涉及的规则完全相同（BM001、BM004），本项与可维护、可测试同值（工作区实测 2,375 / 2,414），五个维度实际只有两个不同的值。门禁栏的「问题按规则分布」比它更细，这里不再重复。 | H11: 不展示 | I11: — | J11: 涉及部分规则（按维度筛选） | K11: — | L11: — | M11: 维度遵从度 | N11: A1 有区分度 | O11: callable | P11: rules.conformity.function.readability | Q11: 解析失败的文件按不达标计（unknown_policy = fail） | R11: 没有命中任何函数级相关规则的 callable 数 | S11: callable 数量（unknown_policy = fail 时再加解析失败的文件数） | T11: 不能 | U11: 98.4%（2,375 / 2,414） | V11: 97.9%（47 / 48） | W11: — | X11: 规则统计指标
A12: 11 | B12: 函数级 | C12: 规则达标率 | D12: 函数级可靠规则遵从度 | E12: 不选入 | F12: 只是把规则命中按质量维度重新分组，且组内数值相同 | G12: 质量维度是规则的分组：知道命中了哪条规则，就知道哪些维度不达标。函数级的安全、可靠两项涉及的规则完全相同（BM002），本项与安全同值（工作区实测 2,410 / 2,414），五个维度实际只有两个不同的值。门禁栏的「问题按规则分布」比它更细，这里不再重复。 | H12: 不展示 | I12: — | J12: 涉及部分规则（按维度筛选） | K12: — | L12: — | M12: 维度遵从度 | N12: A1 有区分度 | O12: callable | P12: rules.conformity.function.reliability | Q12: 解析失败的文件按不达标计（unknown_policy = fail） | R12: 没有命中任何函数级相关规则的 callable 数 | S12: callable 数量（unknown_policy = fail 时再加解析失败的文件数） | T12: 不能 | U12: 99.8%（2,410 / 2,414） | V12: 97.9%（47 / 48） | W12: — | X12: 规则统计指标
A13: 12 | B13: 函数级 | C13: 规则达标率 | D13: 函数级安全规则遵从度 | E13: 不选入 | F13: 只是把规则命中按质量维度重新分组，且组内数值相同 | G13: 质量维度是规则的分组：知道命中了哪条规则，就知道哪些维度不达标。函数级的安全、可靠两项涉及的规则完全相同（BM002），本项与可靠同值（工作区实测 2,410 / 2,414），五个维度实际只有两个不同的值。门禁栏的「问题按规则分布」比它更细，这里不再重复。 | H13: 不展示 | I13: — | J13: 涉及部分规则（按维度筛选） | K13: — | L13: — | M13: 维度遵从度 | N13: A1 有区分度 | O13: callable | P13: rules.conformity.function.security | Q13: 解析失败的文件按不达标计（unknown_policy = fail） | R13: 没有命中任何函数级相关规则的 callable 数 | S13: callable 数量（unknown_policy = fail 时再加解析失败的文件数） | T13: 不能 | U13: 99.8%（2,410 / 2,414） | V13: 97.9%（47 / 48） | W13: — | X13: 规则统计指标
... A54: 53 | B54: 项目级 | C54: 规则达标率 | D54: 项目级可测试规则遵从度 | E54: 不选入 | F54: 只有 0 和 1 两个取值，等价于门禁的通过 / 阻塞 | G54: 项目级把整个分析范围当作 1 个单位，默认的 physical 聚合下只有通过（1）和不通过（0）两个取值，实测 0（0/1）。这个结论就是门禁栏已展示的门禁结论（gate.status），不带新信息（A1）；分母恒为 1，也谈不上比例（A3）。可测试维度只是把规则命中重新分组，不改变这一点。 | H54: 不展示 | I54: — | J54: 涉及部分规则（按维度筛选） | K54: — | L54: — | M54: 项目级遵从度 | N54: A1 有区分度；A3 尺度有效 | O54: 本次分析组整体 | P54: rules.conformity.project.testability | Q54: 解析失败的文件按不达标计（unknown_policy = fail） | R54: 没有任何相关发现条目且无解析失败时为 1，否则 0（view 聚合时为通过的 view 数） | S54: 1（physical 聚合）；view 聚合时为 view 数；有解析失败且 unknown_policy = exclude 时分母为 0（not_applicable） | T54: 不能 | U54: 0%（0 / 1） | V54: 0%（0 / 1） | W54: — | X54: 规则统计指标

Sheet 已排除指标
A1: 不参与评估的 12 项：工具没有给出计算方式
A2: bot-metric 内置的规则里，没有任何一条对应「高效」或「可移植」这两个质量维度。这 12 项指标在源码里被直接写死：value = numerator = denominator = 0，status = not_applicable。全量和单文件两种输入实测都是这个结果，换任何代码都一样，不能当作「达标」来读。所以它们不进入选型评估，也不占「选入 / 不选入」的数量。
A4: 指标标识（bot-metric id） | B4: 指标名称（中文） | C4: 度量级别 | D4: 质量维度 | E4: 源码里写死的位置
A5: rules.conformity.performance_efficiency | B5: 文件级高效规则遵从度 | C5: 模块级 | D5: 高效 | E5: rules.rs:480
A6: rules.conformity.portability | B6: 文件级可移植规则遵从度 | C6: 模块级 | D6: 可移植 | E6: rules.rs:480
A7: rules.coverage.performance_efficiency | B7: 文件级高效规则覆盖率 | C7: 模块级 | D7: 高效 | E7: rules.rs:839
A8: rules.coverage.portability | B8: 文件级可移植规则覆盖率 | C8: 模块级 | D8: 可移植 | E8: rules.rs:839
A9: rules.conformity.function.performance_efficiency | B9: 函数级高效规则遵从度 | C9: 函数级 | D9: 高效 | E9: rules.rs:826
A10: rules.conformity.function.portability | B10: 函数级可移植规则遵从度 | C10: 函数级 | D10: 可移植 | E10: rules.rs:826
A11: rules.coverage.function.performance_efficiency | B11: 函数级高效规则覆盖率 | C11: 函数级 | D11: 高效 | E11: rules.rs:826
A12: rules.coverage.function.portability | B12: 函数级可移植规则覆盖率 | C12: 函数级 | D12: 可移植 | E12: rules.rs:826
A13: rules.conformity.project.performance_efficiency | B13: 项目级高效规则遵从度 | C13: 项目级 | D13: 高效 | E13: rules.rs:826
A14: rules.conformity.project.portability | B14: 项目级可移植规则遵从度 | C14: 项目级 | D14: 可移植 | E14: rules.rs:826
A15: rules.coverage.project.performance_efficiency | B15: 项目级高效规则覆盖率 | C15: 项目级 | D15: 高效 | E15: rules.rs:826
A16: rules.coverage.project.portability | B16: 项目级可移植规则覆盖率 | C16: 项目级 | D16: 可移植 | E16: rules.rs:826
A18: 解除条件：bot-metric 新增对应这两个维度的规则，或接入 clippy 并建立「lint → 质量维度」的映射。

Sheet 展示设计
A1: 插件各处展示什么，数据取自哪里
A2: 五个展示位置编号与界面稿一致（④ 下有两个视图：工作区概览、问题）。口径只有一个来源：所有展示值取自 bot-metric 的输出字段，插件不自行计算。实测值均来自 ripgrep 源码树（工作区）、hiargs.rs（本文件）与 from_low_args（光标处）。
A4: 展示位置 | B4: 展示什么 | C4: 数据来源 | D4: 范围 | E4: 实测值 | F4: 说明
A5: ① 诊断 （波浪线与问题面板；只来自规则，不来自指标） | B5: 函数过长 | C5: 规则 BM001 的问题条目（rust.function.too_large） | D5: 函数级 | E5: 工作区 38 条 | F5: 条目文本自带数字，如「函数体 185 行，上限 50」。
B6: 函数复杂度过高 | C6: 规则 BM004 的问题条目（rust.function.too_complex） | D6: 函数级 | E6: 工作区 6 条 | F6: 条目文本写明圈复杂度 34、上限 20，是单个函数复杂度唯一准确的来源。
B7: unsafe 使用 | C7: 规则 BM002 的问题条目（rust.safety.unsafe_usage） | D7: 函数级以下 | E7: 工作区 5 条 | F7: 每个 unsafe 区域一条，位置精确到列。
B8: 文件过大 | C8: 规则 BM003 的问题条目（rust.file.too_large） | D8: 模块级 | E8: 工作区 2 条 | F8: 挂在文件顶部。
B9: 重复代码块、整文件重复 | C9: 规则 BM006、BM007 的问题条目（duplicated_block、file.exact_duplicate） | D9: 跨模块 | E9: 默认关闭 | F9: 需先打开重复发现开关；跨文件重复只有工作区范围能算。
A10: ② 函数提示 （CodeLens 只在有问题的函数上；悬停在任意函数名上） | B10: 超限的实际值与上限 | C10: 规则 BM001、BM004 的问题条目文本，如“76 code lines exceed the limit of 50 by 26” | D10: 函数级 | E10: 185 行，上限 50，超出 135；圈复杂度 34，上限 20 | F10: 命中规则的函数，悬停里的数字取自条目文本，并写出规则编号与超出量。数字靠解析条目文本，bot-metric 改措辞会缺失，需向它提结构化字段（设计文档 DD-4）。
B11: 正常函数的行数与圈复杂度 | C11: 悬停时对光标所在函数做一次语法项投影（--item-at），取目录里 valueMetric 指向的指标在该语法项上的值；上限用目录里的显示阈值 | D11: 函数级（语法项） | E11: matcher_rust：49 行（上限 50）、圈复杂度 13（上限 20） | F11: 每次约 18 毫秒，结果按「文件#行」缓存，工作区快照一换就丢弃。函数含闭包时是区域平均，可能偏低（设计文档 R-2）。
B12: 悬停里的细条 | C12: 数字原值与上限（catalog 的 threshold） | D12: 函数级 | E12: 185 对 50：绿 5 格红 15 格；49 对 50：绿满格 | F12: 超限时绿段是上限占实际的比例，其余红；没超限时绿段是已用掉上限的比例，其余灰。颜色靠 span 着色，编辑器只保留 color。
B13: 本函数命中了哪条规则 | C13: 问题条目按函数名与起始行归属 | D13: 函数级 | E13: 无额外开销 | F13: 从已有结果里匹配即可。
A14: ③ 文件状态栏 （底栏，跟随当前打开的文件） | B14: 底栏文字 | C14: 本文件的问题总数，再接函数达标 rules.conformity.function 的分子分母 | D14: 本文件 | E14: 有问题：「3 个问题 | 函数达标 47/48」；没问题：只显示「达标」 | F14: 没问题的文件不摆数字，避免让人自己判断这个数好不好。是哪些问题放悬停，底栏才不会随问题种类变长。
B15: 悬停：问题种类 | C15: 本文件的规则命中按规则归类，顺序同规则目录 | D15: 本文件 | E15: 函数过长 1 · unsafe 使用 1 · 函数复杂度过高 1 | F15: 每个种类是一个链接，点击去到该种类的问题。逐条位置不在悬停里列，交给 ① 诊断。
B16: 悬停：指标画像 | C16: 指标目录里声明了 profile（行序与行名）的指标，本文件与工作区并排 | D16: 本文件、工作区 | E16: 函数达标 97.9%（47/48）对 98.3%；平均函数代码行 19.7 行对 8.52 行；平均圈复杂度 4.52 对 2.10 | F16: 与问题不挂钩，没问题的文件悬停里也是这张表。本文件没有值的指标不显示。行序、行名、增减都在目录里改，不动代码。
B17: 悬停末尾 | C17: 这份数据取自哪次分析（producedAt） | D17: 本文件 | E17: 取自 14:32 的保存分析 | F17: 与函数悬停一致。
B18: 画像的十行 | C18: rules.conformity.function、function.lines.average、function.lines.huge_ratio、complexity.cyclomatic.average、complexity.cyclomatic.huge_ratio、complexity.cca.average、complexity.cca.huge_ratio、size.nbnc_lines、safety.unsafe_density、redundancy.commented_code_density | D18: 本文件、工作区 | E18: 10 行，见「实测数据」页 | F18: CCA 复杂度作校正参考，与圈复杂度并列。单文件输入时，本文件的规模就是这个文件的行数。
B19: 点击底栏 | C19: 编辑器里已有的诊断（按规则代号过滤） | D19: 本文件 | E19: 一个问题：直接跳；多个：按种类分组的列表，方向键预览，回车过去 | F19: 位置与文案取自诊断，与问题面板一致。没有问题时点击打开工作区面板。
A20: ④ 侧栏 （工作区概览 与「问题」视图，整个工作区） | B20: 工作区规模、unsafe 密度 | C20: size.nbnc_lines、safety.unsafe_density | D20: 工作区 | E20: 40,756 行、0.022%
B21: 平均文件行数、超大文件比例 | C21: file.lines.average、file.lines.huge_ratio | D21: 工作区 | E21: 370.5 行、1.8%（2/110）
B22: 函数：平均行数、平均圈复杂度、两个超限比例 | C22: function.lines.average、complexity.cyclomatic.average、两个 huge_ratio | D22: 工作区 | E22: 8.52 行、2.10、1.57%（38/2,414）、0.25%（6/2,414）
B23: 平均 CCA 复杂度、CCA 超限比例 | C23: complexity.cca.average、complexity.cca.huge_ratio | D23: 工作区 | E23: 2.02、0.21%（5/2,414） | F23: 与圈复杂度并列，作校正参考。
B24: 代码重复率、整文件重复率 | C24: duplication.code_ratio、duplication.file_exact_ratio | D24: 工作区 | E24: 5.53%、0 | F24: 跨文件重复只有工作区范围能算。
B25: 注释代码密度、超大目录比例 | C25: redundancy.commented_code_density、directory.huge_ratio | D25: 工作区 | E25: 0.098 段 / 千行、0%（0/60 个目录）
B26: 不摆达标率 | C26: 文件达标率 rules.conformity.total 取消选入；函数达标率只在 ③ 出现 | D26: — | E26: — | F26: 面板给的是门禁结论与按规则的分布，不是要读者自己判断好坏的比例（见「指标清单」的「产品取舍」）。
B27: 「问题」视图：全部问题 | C27: 快照里的规则命中（与诊断同源），按规则分类、按文件分组 | D27: 工作区 | E27: 51 条，分布在 25 个文件；函数过长 38、复杂度过高 6、unsafe 5、文件过大 2 | F27: 顶部按规则筛选，文件行可折叠，点一条跳到位置；筛选与折叠会记住。原生问题面板不能这样分类，所以另开视图。
A28: ⑤ 门禁栏 （工作区面板顶部与底栏） | B28: 门禁结论与阻塞条目数 | C28: gate.status、gate.blocking_findings | D28: 工作区 | E28: 已阻塞，52 条
B29: 问题按规则分布 | C29: gate.findings_by_rule | D29: 工作区 | E29: 过长 38、复杂 6、unsafe 5、文件过大 2、目标未达成 1 | F29: 代替按质量维度切分的遵从度。
B30: 7 项质量目标 | C30: quality_targets 的 current、target、status | D30: 工作区 | E30: 6 项有基线可判：5 项达标，平均文件行数未达标（370.5 > 300）；代码规模增长缺基线，不计达标也不计超标 | F30: BM005 不做诊断，改放这里。面板显示「5 / 6 达标」。

Sheet 规则与门禁
A1: 规则与质量目标：选入指标的对应关系
A2: 规则（BM001~BM007）给出带位置的诊断，质量目标（quality_targets）给出项目级的达标判定。选入的指标里，被它们使用的会按规则或目标的方式呈现，两者都不使用的只作参考值。下面的数量由「指标清单」页统计。
A4: 选入 15 项的构成
A5: 类别 | B5: 项数 | C5: 说明
A6: 有对应规则 | B6: =COUNTIFS(指标清单!$E$2:$E$54,"选入",指标清单!$J$2:$J$54,"<>—") -> 7 | C6: 其中 rules.conformity.function 是 BM001、BM002、BM004 三条规则的达标率汇总（文件达标率 rules.conformity.total 已取消选入）
A7: 有对应质量目标 | B7: =COUNTIFS(指标清单!$E$2:$E$54,"选入",指标清单!$K$2:$K$54,"<>—") -> 7
A8: 两者兼有 | B8: =COUNTIFS(指标清单!$E$2:$E$54,"选入",指标清单!$J$2:$J$54,"<>—",指标清单!$K$2:$K$54,"<>—") -> 3 | C8: 代码重复率、整文件重复率、unsafe 密度
A9: 只作参考值 | B9: =COUNTIFS(指标清单!$E$2:$E$54,"选入",指标清单!$J$2:$J$54,"—",指标清单!$K$2:$K$54,"—") -> 4 | C9: CCA 两项、注释代码密度、超大目录比例
A10: 核对 | B10: =IF(B6+B7-B8+B9=COUNTIF(指标清单!$E$2:$E$54,"选入"),"一致","不一致") -> 一致 | C10: 有规则 + 有目标 − 两者兼有 + 只作参考值 应等于选入总数
A12: 七条规则
A13: 编号 | B13: 名称 | C13: 对应指标 | D13: 判定对象 | E13: 度量级别 | F13: ripgrep 实测 | G13: 说明
A14: BM001 | B14: 函数过长 | C14: function.lines.huge_ratio | D14: 函数 | E14: 函数级 | F14: 38 条 | G14: 函数体超过 50 行。
A15: BM004 | B15: 函数复杂度过高 | C15: complexity.cyclomatic.huge_ratio | D15: 函数 | E15: 函数级 | F15: 6 条 | G15: 圈复杂度超过 20。
A16: BM002 | B16: unsafe 使用 | C16: safety.unsafe_density | D16: unsafe 区域 | E16: 函数级以下 | F16: 5 条 | G16: 每个 unsafe 区域一条。
A17: BM003 | B17: 文件过大 | C17: file.lines.huge_ratio | D17: 文件 | E17: 模块级 | F17: 2 条 | G17: 文件超过 2000 行。
A18: BM006 | B18: 重复代码块 | C18: duplication.code_ratio | D18: 重复窗口 | E18: 跨模块 | F18: 默认关闭 | G18: 需先打开重复发现开关。
A19: BM007 | B19: 文件完全重复 | C19: duplication.file_exact_ratio | D19: 文件 | E19: 模块级 | F19: 默认关闭 | G19: 需先打开重复发现开关。
A20: BM005 | B20: 质量目标未达成 | C20: （无，见下表） | D20: 项目 | E20: 项目级 | F20: 1 条 | G20: 它是质量目标未达成的汇总条目，不做成诊断，改放门禁栏，以免与质量目标重复。
A22: 七项质量目标（均为项目级，数值为 ripgrep 实测）
A23: 配置字段 | B23: 通俗名称 | C23: 依据指标 | D23: 目标 | E23: 当前值 | F23: 状态 | G23: 说明
A24: max_average_file_lines | B24: 平均文件行数上限 | C24: file.lines.average | D24: ≤ 300 行 | E24: 370.5 行 | F24: 未达标 | G24: ripgrep 唯一未达标的目标，也是那条 BM005 的来源。
A25: max_average_function_lines | B25: 平均函数行数上限 | C25: function.lines.average | D25: ≤ 30 行 | E25: 8.52 行 | F25: 达标
A26: max_average_cyclomatic | B26: 平均圈复杂度上限 | C26: complexity.cyclomatic.average | D26: ≤ 5 | E26: 2.10 | F26: 达标
A27: max_code_duplication_ratio | B27: 代码重复率上限 | C27: duplication.code_ratio | D27: ≤ 10% | E27: 5.53% | F27: 达标
A28: max_file_duplication_ratio | B28: 整文件重复率上限 | C28: duplication.file_exact_ratio | D28: ≤ 4% | E28: 0% | F28: 达标
A29: max_unsafe_density | B29: unsafe 密度上限 | C29: safety.unsafe_density | D29: ≤ 10% | E29: 0.022% | F29: 达标
A30: max_code_size_growth_ratio | B30: 代码规模增长率上限 | C30: size.nbnc_lines | D30: 增长 ≤ 0% | E30: — | F30: 不适用 | G30: 需传入基线才能计算；缺基线时门禁记为不完整。

Sheet 实测数据
A1: 度量级别 | B1: 指标名称（中文） | C1: 指标标识（bot-metric id） | D1: 结论 | E1: 工作区（ripgrep 全量） | F1: 本文件（hiargs.rs） | G1: 光标处（from_low_args）
A2: 函数级 | B2: 平均函数代码行 | C2: function.lines.average | D2: 选入 | E2: 8.52 行（20,574 / 2,414） | F2: 19.71 行（946 / 48） | G2: 41.2 行（206 / 5）
A3: 函数级 | B3: 超大函数比例 | C3: function.lines.huge_ratio | D3: 选入 | E3: 1.57%（38 / 2,414） | F3: 2.08%（1 / 48） | G3: 20.0%（1 / 5）
A4: 函数级 | B4: 平均圈复杂度 | C4: complexity.cyclomatic.average | D4: 选入 | E4: 2.10（5,068 / 2,414） | F4: 4.52（217 / 48） | G4: 9.20（46 / 5）
A5: 函数级 | B5: 超大圈复杂度比例 | C5: complexity.cyclomatic.huge_ratio | D5: 选入 | E5: 0.25%（6 / 2,414） | F5: 2.08%（1 / 48） | G5: 20.0%（1 / 5）
A6: 函数级 | B6: 平均 CCA 复杂度 | C6: complexity.cca.average | D6: 选入 | E6: 2.02（4,877 / 2,414） | F6: 4.29（206 / 48） | G6: 9.00（45 / 5）
A7: 函数级 | B7: CCA 超限比例 | C7: complexity.cca.huge_ratio | D7: 选入 | E7: 0.21%（5 / 2,414） | F7: 2.08%（1 / 48） | G7: 20.0%（1 / 5）
A8: 函数级 | B8: 函数级总体规则遵从度 | C8: rules.conformity.function | D8: 选入 | E8: 98.3%（2,372 / 2,414） | F8: 97.9%（47 / 48） | G8: —
A9: 函数级 | B9: CCA 阈值满足度 | C9: complexity.cca.adequacy | D9: 不选入 | E9: 99.8%（2,409 / 2,414） | F9: 97.9%（47 / 48） | G9: 80.0%（4 / 5）
A10: 函数级 | B10: 函数级可维护规则遵从度 | C10: rules.conformity.function.maintainability | D10: 不选入 | E10: 98.4%（2,375 / 2,414） | F10: 97.9%（47 / 48） | G10: —
A11: 函数级 | B11: 函数级可读规则遵从度 | C11: rules.conformity.function.readability | D11: 不选入 | E11: 98.4%（2,375 / 2,414） | F11: 97.9%（47 / 48） | G11: —
A12: 函数级 | B12: 函数级可靠规则遵从度 | C12: rules.conformity.function.reliability | D12: 不选入 | E12: 99.8%（2,410 / 2,414） | F12: 97.9%（47 / 48） | G12: —
... A54: 项目级 | B54: 项目级可测试规则遵从度 | C54: rules.conformity.project.testability | D54: 不选入 | E54: 0%（0 / 1） | F54: 0%（0 / 1） | G54: —
A56: 读法：比例类指标显示为百分比，括号内是「分子 / 分母」；平均值类括号内是「总和 / 个数」。「—」表示该范围不产生这项指标；「不适用」表示工具明确判定不适用。
A57: 三个范围：工作区 = ripgrep 全量（110 个文件、40,756 行有效代码、2,414 个函数）；本文件 = hiargs.rs（1,107 行、48 个函数）；光标处 = 只分析 from_low_args 所在区域。

Sheet 术语说明
A1: 术语说明
A3: 术语 | B3: 通俗解释 | C3: 备注
A4: 有效代码行（NBNC 行） | B4: 去掉空行和纯注释行之后的行数；代码后面带尾注释的行算 1 行。本表所有「行数」都按这个口径。 | C4: NBNC = Non-Blank Non-Comment
A5: 函数（callable） | B5: 自由函数、嵌套 fn、impl 方法与关联函数、带默认体的 trait 方法。不含闭包。 | C5: 表中的「函数级」指标都以它为单位
A6: 圈复杂度 | B6: 衡量函数里有多少条独立执行路径。从 1 开始，遇到 if、for、loop、while、match 分支（首分支不计）、?、let-else、&&、|| 各加 1。
A7: CCA 复杂度 | B7: 圈复杂度的变体：match 的各分支体本身都不含决策点时，整条 match 只算 1；否则与圈复杂度相同。 | C7: 阈值 20 参考 JSF C++ 编码标准，可配置
A8: 超大 / 超限比例（huge_ratio） | B8: 超过阈值的对象占全部对象的比例。「超过」是严格大于阈值才算。 | C8: CCA 满足度相反，用「小于等于」判满足
A9: 遵从度 | B9: 没有触发相关规则的对象占比，越高越好。
A10: 覆盖率 | B10: 成功解析的对象占比。只有文件解析失败时才会低于 100%。
A11: 质量维度 | B11: 规则的分类：可维护、可读、可靠、安全、可测试；另有高效、可移植两个维度，工具没有给出计算方式。
A12: physical 聚合 | B12: 默认的聚合方式。项目级把整个分析范围算作 1 个单位，所以项目级遵从度只有 0 和 1。
A13: unknown_policy | B13: 解析失败的文件怎么处理。fail（默认）：算进分母、按不达标计；exclude：不计入。 | C13: 见设计文档 DD-5
A14: 质量目标（quality_targets） | B14: 配置文件里的 7 个项目级上限，门禁据此给出「达标 / 未达标」。 | C14: 见「规则与门禁」页
A15: 门禁 | B15: bot-metric 的 check 命令：根据规则命中和质量目标给出通过或阻塞。
A16: 光标处取值（item 投影） | B16: 传入光标位置，只分析光标所在的语法项，得到函数级取值，每次约 18 毫秒。对个别指标，这种范围下分母会失真。函数悬停里，命中规则的函数用规则条目里的数字，没有问题的函数才用这种取值；函数含闭包时得到的是区域平均，可能偏低。 | C16: 设计文档 DD-4、R-2
A17: rust-analyzer | B17: 编辑器里已有的 Rust 语言服务，已经提供语法和编译诊断。 | C17: 与它重复的指标不选入
A18: BM001~BM007 | B18: bot-metric 的七条内置规则：BM001 函数过长、BM002 unsafe 使用、BM003 文件过大、BM004 函数复杂度过高、BM005 质量目标未达成、BM006 重复代码块、BM007 文件完全重复。 | C18: BM1xx / BM2xx 是分析完整性诊断，如 BM201 语法错误
A19: 五个展示位置 | B19: ① 诊断 ② 函数提示（CodeLens、悬停） ③ 文件状态栏 ④ 侧栏（工作区概览、问题视图） ⑤ 门禁栏。 | C19: 见「展示设计」页与界面稿
